Workbook

Sheet Main
B1: Safe Owner Report
B4: This report gives you a summary of your safes. It allows you to carry out the first level of necessary controls within the framework of the security policy.
B5: It contains information about user access to your safes and their credentials. In addition, it shows the results of various verifications and security checks.
B6: Additionally, a time-based analysis is conducted on the data to show any changes that have occurred since the last analysis was performed by Brainwave.
B8: To use this report, click on one of the links below. You will then be redirected to the corresponding dashboard which will show you the summary of the results.
B9: To access the details of a result, simply click on the relevant title. You will then be redirected to the corresponding tab. The cell allowing you to filter
B10: the results will be automatically selected and, you can proceed with your analysis.
C15: Monitoring of My Safes | J15: My Safes Details
C16: Scope | J16: List of Safes I Own
C17: New CyberArk Users by Type | J17: List of Users Having Access to My Safes
C18: Group Changes | J18: List of Groups Providing Access to My Safes
C19: Credential Changes | J19: List of Credentials Secured in My Safes
C20: Identified Risk Issues | J20: List of Issues Detected in My Safes
C21: Identified Quality Issues

Sheet SafeOwner KPIs
B1: Monitoring of My Safes
A2: ↓ | B2: Scope
A33: ↓ | B33: New CyberArk Users by Type
A54: ↓ | B54: Group Changes
A77: ↓ | B77: Credential Changes
A99: ↓ | B99: Identified Risk Issues
A148: ↓ | B148: Identified Quality Issues

Sheet data
A1: SAFES
A3: newownedsafes | B3: =COUNTIF(safes!A$2:A$900001,"New") -> 0
A4: totalownedsafes | B4: =COUNTA(safes!E$2:E$900000)-1 -> 2
A6: USERS
B7: All | C7: DiffNew | D7: New | E7: DiffModif | F7: Modified | G7: DiffDel | H7: Deleted
A8: activeusers | B8: =COUNTA(users!C$2:C$900000)-1 -> 37 | C8: =B8-D8 -> 14 | D8: =COUNTIF(users!A$2:A$900000,"New") -> 23 | E8: =B8-F8 -> 30 | F8: =COUNTIF(users!A$2:A$900000,"Modified") -> 7 | G8: =B8-H8 -> 37 | H8: =COUNTIF(users!A$2:A$900000,"Deleted") -> 0
A9: bookingusers | B9: =COUNTIF(users!B$2:B$900001,"Booking") -> 31 | C9: =B9-D9 -> 12 | D9: =COUNTIFS(users!B$2:B$900001,"Booking",users!A$2:A$900001,"New") -> 19 | E9: =B9-F9 -> 26 | F9: =COUNTIFS(users!B$2:B$900001,"Booking",users!A$2:A$900001,"Modified") -> 5 | G9: =B9-H9 -> 31 | H9: =COUNTIFS(users!B$2:B$900001,"Booking",users!A$2:A$900001,"Deleted") -> 0
A10: effectiveusers | B10: =B8-B9 -> 6 | C10: =B10-D10 -> 2 | D10: =D8-D9 -> 4 | E10: =B10-F10 -> 4 | F10: =F8-F9 -> 2 | G10: =B10-H10 -> 6 | H10: =H8-H9 -> 0
A11: EPVusers | B11: =COUNTIF(users!B$2:B$900001,"EPVUser") -> 1 | C11: =B11-D11 -> 1 | D11: =COUNTIFS(users!B$2:B$900001,"EPVUser",users!A$2:A$900001,"New") -> 0 | E11: =B11-F11 -> 0 | F11: =COUNTIFS(users!B$2:B$900001,"EPVUser",users!A$2:A$900001,"Modified") -> 1 | G11: =B11-H11 -> 1 | H11: =COUNTIFS(users!B$2:B$900001,"EPVUser",users!A$2:A$900001,"Deleted") -> 0
A12: AIMusers | B12: =COUNTIF(users!B$2:B$900001,"AIMAccount") -> 3 | C12: =B12-D12 -> 0 | D12: =COUNTIFS(users!B$2:B$900001,"AIMAccount",users!A$2:A$900001,"New") -> 3 | E12: =B12-F12 -> 3 | F12: =COUNTIFS(users!B$2:B$900001,"AIMAccount",users!A$2:A$900001,"Modified") -> 0 | G12: =B12-H12 -> 3 | H12: =COUNTIFS(users!B$2:B$900001,"AIMAccount",users!A$2:A$900001,"Deleted") -> 0
A13: OtherTypes | B13: =B10-B11-B12 -> 2 | C13: =C10-C11-C12 -> 1 | D13: =D10-D11-D12 -> 1 | E13: =E10-E11-E12 -> 1 | F13: =F10-F11-F12 -> 1 | G13: =G10-G11-G12 -> 2 | H13: =H10-H11-H12 -> 0
A14: Contractors | B14: =COUNTIF(users!AK$2:AK$90000,0) -> 3
A16: GROUPS
B17: All | C17: DiffNew | D17: New | E17: DiffModif | F17: Modified | G17: DiffDel | H17: Deleted
A18: groups | B18: =COUNTA(groups!D$2:D$900000)-1 -> 10 | C18: =B18-D18 -> 6 | D18: =COUNTIF(groups!A$2:A$900000,"New") -> 4 | E18: =B18-F18 -> 6 | F18: =COUNTIF(groups!A$2:A$900000,"Modified") -> 4 | G18: =B18-H18 -> 10 | H18: =COUNTIF(groups!A$2:A$900000,"Deleted") -> 0
A19: parentgroups | B19: =COUNTIF(groups!N$2:N$900000,">0") -> 4 | C19: =B18-D19 -> 10 | D19: =COUNTIFS(groups!A$2:A$900000,"New",groups!N$2:N$900000,">0") -> 0 | E19: =B18-F19 -> 8 | F19: =COUNTIFS(groups!A$2:A$900000,"Modified",groups!N$2:N$900000,">0") -> 2 | G19: =B18-H19 -> 10 | H19: =COUNTIFS(groups!A$2:A$900000,"Deleted",groups!N$2:N$900000,">0") -> 0
A21: CREDENTIALS
B22: All | C22: DiffNew | D22: New | E22: DiffModif | F22: Modified | G22: DiffDel | H22: Deleted
A23: credentials | B23: =COUNTA(credentials!B$2:B$900000)-1 -> 104 | C23: =B23-D23 -> 90 | D23: =COUNTIF(credentials!A$2:A$900000,"New") -> 14 | E23: =B23-F23 -> 14 | F23: =COUNTIF(credentials!A$2:A$900000,"Modified") -> 90 | G23: =B23-H23 -> 104 | H23: =COUNTIF(credentials!A$2:A$900000,"Deleted") -> 0
A24: DiffCPMdisabled | B24: =B23-B25 -> 91
A25: credentials with CPM disabled | B25: =COUNTIF(credentials!G$2:G$900000,"0") -> 13 | C25: =B25-D25 -> 13 | D25: =COUNTIFS(credentials!G$2:G$900000,0,credentials!A$2:A$900000,"New") -> 0 | E25: =B25-F25 -> 0 | F25: =COUNTIFS(credentials!G$2:G$900000,0,credentials!A$2:A$900000,"Modified") -> 13 | G25: =B25-H25 -> 13 | H25: =COUNTIFS(credentials!G$2:G$900000,0,credentials!A$2:A$900000,"Deleted") -> 0
A26: DiffCPMfailed | B26: =B23-B27 -> 94
A27: credentials with failed CPM | B27: =COUNTIF(credentials!H$2:H$900000,"failed") -> 10 | C27: =B27-D27 -> 10 | D27: =COUNTIFS(credentials!H$2:H$900000,"failed",credentials!A$2:A$900000,"New") -> 0 | E27: =B27-F27 -> 0 | F27: =COUNTIFS(credentials!H$2:H$900000,"failed",credentials!A$2:A$900000,"Modified") -> 10 | G27: =B27-H27 -> 10 | H27: =COUNTIFS(credentials!H$2:H$900000,"failed",credentials!A$2:A$900000,"Deleted") -> 0
A29: DETECTED ISSUES
B30: All | C30: DiffValue | D30: Value | E30: New | I30: ControlDisplayname
A31: Remaining Active Users | B31: =B8 -> 37 | C31: =B31-D31 -> 32 | D31: =COUNTIF(controldefects!C$2:C$900000,A31) -> 5 | E31: =COUNTIFS(controldefects!C$2:C$900000,A31,controldefects!A$2:A$900000,"New") -> 5 | F31: =_xlfn.CONCAT(" + ",E31) -> + 5 | I31: Active user accounts for which the owner has departed and have access to a safe
A32: New Credentials without CPM | B32: =B23 -> 104 | C32: =B32-D32 -> 91 | D32: =COUNTIF(controldefects!C$2:C$900000,A32) -> 13 | E32: =COUNTIFS(controldefects!C$2:C$900000,A32,controldefects!A$2:A$900000,"New") -> 0 | F32: =_xlfn.CONCAT(" + ",E32) -> + 0 | I32: CyberArk credentials for which automatic password rotation is disabled
A33: Orphaned Users | B33: =B8 -> 37 | C33: =B33-D33 -> 36 | D33: =COUNTIF(controldefects!C$2:C$900000,A33) -> 1 | E33: =COUNTIFS(controldefects!C$2:C$900000,A33,controldefects!A$2:A$900000,"New") -> 0 | F33: =_xlfn.CONCAT(" + ",E33) -> + 0 | I33: Orphaned accounts with access to a safe
A34: Users with Direct Authorization to my Safes | B34: =B8 -> 37 | C34: =B34-D34 -> 31 | D34: =COUNTIF(controldefects!C$2:C$900000,A34) -> 6 | E34: =COUNTIFS(controldefects!C$2:C$900000,A34,controldefects!A$2:A$900000,"New") -> 0 | F34: =_xlfn.CONCAT(" + ",E34) -> + 0 | I34: Users that have at least one direct permission to a safe
A35: Users that Can Manage my Safes and Use Their Credentials | B35: =B8 -> 37 | C35: =B35-D35 -> 3 | D35: =COUNTIF(controldefects!C$2:C$900000,A35) -> 34 | E35: =COUNTIFS(controldefects!C$2:C$900000,A35,controldefects!A$2:A$900000,"New") -> 23 | F35: =_xlfn.CONCAT(" + ",E35) -> + 23 | I35: Users that can both manage the safe and use its contents
A36: Users that Can Access to the Vault and my Safes | B36: =B8 -> 37 | C36: =B36-D36 -> 13 | D36: =COUNTIF(controldefects!C$2:C$900000,A36) -> 24 | E36: =COUNTIFS(controldefects!C$2:C$900000,A36,controldefects!A$2:A$900000,"New") -> 17 | F36: =_xlfn.CONCAT(" + ",E36) -> + 17 | I36: Users with both access to the vault and access to a safe inside the vault
A37: Contractors who Can Manage my Safes without Expiration | B37: =B14 -> 3 | C37: =B37-D37 -> 2 | D37: =COUNTIF(controldefects!C$2:C$900000,A37) -> 1 | E37: =COUNTIFS(controldefects!C$2:C$900000,A37,controldefects!A$2:A$900000,"New") -> 1 | F37: =_xlfn.CONCAT(" + ",E37) -> + 1 | I37: Contractors with no expiration date that can manage a safe
A38: Contractors who Can Use my Credentials without Expiration | B38: =B14 -> 3 | C38: =B38-D38 -> 2 | D38: =COUNTIF(controldefects!C$2:C$900000,A38) -> 1 | E38: =COUNTIFS(controldefects!C$2:C$900000,A38,controldefects!A$2:A$900000,"New") -> 1 | F38: =_xlfn.CONCAT(" + ",E38) -> + 1 | I38: Contractors without an expiration date that can access a safe
A39: Dormant Active Users | B39: =B8 -> 37 | C39: =B39-D39 -> 28 | D39: =COUNTIF(controldefects!C$2:C$900000,A39) -> 9 | E39: =COUNTIFS(controldefects!C$2:C$900000,A39,controldefects!A$2:A$900000,"New") -> 4 | F39: =_xlfn.CONCAT(" + ",E39) -> + 4 | I39: Unused user accounts giving access to a safe
A40: Disabled Users | D40: =COUNTIF(controldefects!C$2:C$900000,A40) -> 0 | E40: =COUNTIFS(controldefects!C$2:C$900000,A40,controldefects!A$2:A$900000,"New") -> 0 | F40: =_xlfn.CONCAT(" + ",E40) -> + 0 | I40: Disabled user accounts giving access to a safe
A41: Empty Groups Giving Access to my Credentials | B41: =B18 -> 10 | C41: =B41-D41 -> 9 | D41: =COUNTIF(controldefects!C$2:C$900000,A41) -> 1 | E41: =COUNTIFS(controldefects!C$2:C$900000,A41,controldefects!A$2:A$900000,"New") -> 0 | F41: =_xlfn.CONCAT(" + ",E41) -> + 0 | I41: Empty groups giving access to a safe
A42: Groups with Only Disabled Members | B42: =B18 -> 10 | C42: =B42-D42 -> 10 | D42: =COUNTIF(controldefects!C$2:C$900000,A42) -> 0 | E42: =COUNTIFS(controldefects!C$2:C$900000,A42,controldefects!A$2:A$900000,"New") -> 0 | F42: =_xlfn.CONCAT(" + ",E42) -> + 0 | I42: Groups with only disabled accounts giving access to a safe
A43: My Empty Safes | B43: =B4 -> 2 | C43: =B43-D43 -> 2 | D43: =COUNTIF(controldefects!C$2:C$900000,A43) -> 0 | E43: =COUNTIFS(controldefects!C$2:C$900000,A43,controldefects!A$2:A$900000,"New") -> 0 | F43: =_xlfn.CONCAT(" + ",E43) -> + 0 | I43: The safe is empty
A44: My Safes without Access | B44: =B4 -> 2 | C44: =B44-D44 -> 2 | D44: =COUNTIF(controldefects!C$2:C$900000,A44) -> 0 | E44: =COUNTIFS(controldefects!C$2:C$900000,A44,controldefects!A$2:A$900000,"New") -> 0 | F44: =_xlfn.CONCAT(" + ",E44) -> + 0 | I44: Safe accounts and groups giving no access

Sheet safes
A1: status | B1: safe_displayname | C1: description | D1: vault_displayname | E1: safe_code | F1: sensitivitylevel | G1: sensitivityreason | H1: category | I1: NbCredentials | J1: NbCredentialsActiveCPM | K1: NbCredentialsWithoutCPM | L1: NbCredentialsFailedCPM | M1: NbPlatform | N1: NbDistinctResources | O1: NbUsers | P1: NbActiveUsers | Q1: NbEPVusers | R1: NbAIMusers | S1: NbNonEPVandNonAIMusers | T1: NbBuiltinUsers | U1: NbGroups | V1: NbActiveIdentities | W1: NbActiveContractors | X1: NbOrganization | Y1: NewCredentialsList
A2: Modified | B2: Laptops | C2: Credentials for Laptops | D2: EXTERNAL-VAULT | E2: Laptops_EXTERNAL-VAULT | I2: 104 | J2: 91 | K2: 13 | L2: 10 | M2: 1 | N2: 22 | O2: 34 | P2: 12 | Q2: 12 | R2: 0 | S2: 0 | T2: 0 | U2: 10 | V2: 8 | W2: 0 | X2: 18
A3: Modified | B3: Laptops | C3: Credentials for Laptops | D3: EXTERNAL-VAULT | E3: Laptops_EXTERNAL-VAULT | I3: 104 | J3: 91 | K3: 13 | L3: 10 | M3: 1 | N3: 22 | O3: 34 | P3: 12 | Q3: 12 | R3: 0 | S3: 0 | T3: 0 | U3: 10 | V3: 8 | W3: 0 | X3: 18

Sheet users
A1: status | B1: UserType | C1: user_identifier | D1: user_login | E1: user_username | F1: repository_code | G1: repository_displayname | H1: repository_repositorytype | I1: user_givenname | J1: user_surname | K1: user_mail | L1: user_service | M1: user_logincount | N1: user_lastlogindate | O1: user_expiredate | P1: user_creationdate | Q1: user_employeenumber | R1: user_smartcardrequired | S1: user_locked | T1: user_badpasswordcount | U1: user_dontexpirepassword | V1: user_passwordnotrequired | W1: user_passwordexpired | X1: user_passwordcantchange | Y1: user_passwordlastsetdate | Z1: user_nextpwdchangedate | AA1: recon_noownercode | AB1: recon_leavedate | AC1: recon_rulename | AD1: recon_description | AE1: recon_comment | AF1: recon_reconciliationdate | AG1: identity_hrcode | AH1: identity_fullname | AI1: identity_givenname | AJ1: identity_surname | AK1: identity_internal | AL1: identity_active | AM1: identity_mail | AN1: identity_arrivaldate | AO1: identity_departuredate | AP1: user_groupchanged | AQ1: user_permissionchanged | AR1: user_bwa_accountanalytics_riskrank | AS1: user_bwa_accountanalytics_maxrisklevel | AT1: user_bwa_accountanalytics_nbrisks | AU1: user_bw_pam_usermetrics_nb_safes | AV1: user_bw_pam_usermetrics_nb_safes_cpm_inactive | AW1: user_bw_pam_usermetrics_nb_safes_cpm_active | AX1: user_bw_pam_usermetrics_nb_safes_use | AY1: user_bw_pam_usermetrics_nb_safes_manage | AZ1: user_bw_pam_usermetrics_nb_secrets_cpm_inactive | BA1: user_bw_pam_usermetrics_nb_secrets | BB1: user_bw_pam_usermetrics_nb_secrets_cpm_active | BC1: user_bw_pam_usermetrics_nb_resources | BD1: user_bw_pam_usermetrics_nb_resources_cpm_inactive | BE1: user_bw_pam_usermetrics_nb_resources_cpm_active | BF1: user_bw_pam_usermetrics_nb_platforms | BG1: nb_permission | BH1: user_bwa_accountanalytics_nbdirectright | BI1: user_bwa_accountanalytics_nbdirectgroup
A2: Identical | B2: Booking | C2: CN=Alexis GARDNER,OU=Users,OU=ACME,DC=acme,DC=corp | D2: AGARDNER14 | E2: Alexis GARDNER | F2: ACME | G2: ACME | H2: AD | I2: Alexis | K2: agardner14@acme.com | M2: 0 | P2: 42298 | R2: false | S2: false | T2: 0 | U2: true | V2: false | W2: false | X2: false | AA2: leave | AB2: 44774 | AC2: AD_mail_mail | AD2: identity is not working any more for the company today | AE2: Alexis GARDNER (ID0000962) | AF2: 44774 | AP2: true | AQ2: true | AR2: 2 | AS2: 4 | AT2: 12 | AU2: 20 | AV2: 14 | AW2: 7 | AX2: 14 | AY2: 16 | AZ2: 73 | BA2: 452 | BB2: 379 | BC2: 136 | BD2: 62 | BE2: 102 | BF2: 4 | BG2: 1 | BH2: 0 | BI2: 22
A3: Identical | B3: Booking | C3: CN=Alfredo CASEY,OU=Users,OU=ACME,DC=acme,DC=corp | D3: ACASEY14 | E3: Alfredo CASEY | F3: ACME | G3: ACME | H3: AD | I3: Alfredo | K3: acasey14@acme.com | M3: 0 | P3: 42298 | R3: false | S3: false | T3: 0 | U3: true | V3: false | W3: false | X3: false | AC3: AD_mail_mail | AD3: AD_mail_mail | AE3: AD_mail_mail | AF3: 44774 | AG3: ID0000037 | AH3: Alfredo CASEY | AI3: Alfredo | AJ3: CASEY | AK3: 1 | AL3: true | AM3: acasey14@acme.com | AN3: 40113 | AP3: true | AQ3: true | AR3: 15 | AS3: 3 | AT3: 10 | AU3: 27 | AV3: 15 | AW3: 8 | AX3: 19 | AY3: 21 | AZ3: 77 | BA3: 457 | BB3: 380 | BC3: 141 | BD3: 66 | BE3: 103 | BF3: 5 | BG3: 1 | BH3: 0 | BI3: 36
A4: Modified | B4: Booking | C4: CN=Allan GARRETT,OU=Users,OU=ACME,DC=acme,DC=corp | D4: AGARRETT12 | E4: Allan GARRETT | F4: ACME | G4: ACME | H4: AD | I4: Allan | K4: agarrett12@acme.com | M4: 0 | P4: 42298 | R4: false | S4: false | T4: 0 | U4: true | V4: false | W4: false | X4: false | AC4: AD_mail_mail | AD4: AD_mail_mail | AE4: AD_mail_mail | AF4: 44774 | AG4: ID0000689 | AH4: Allan GARRETT | AI4: Allan | AJ4: GARRETT | AK4: 1 | AL4: true | AM4: agarrett12@acme.com | AN4: 38721 | AP4: true | AQ4: true | AR4: 13 | AS4: 3 | AT4: 11 | AU4: 46 | AV4: 15 | AW4: 25 | AX4: 38 | AY4: 33 | AZ4: 63 | BA4: 382 | BB4: 319 | BC4: 121 | BD4: 57 | BE4: 88 | BF4: 6 | BG4: 19 | BH4: 0 | BI4: 23
A5: New | B5: Booking | C5: CN=Amber WRIGHT,OU=Users,OU=ACME,DC=acme,DC=corp | D5: AWRIGHT10 | E5: Amber WRIGHT | F5: ACME | G5: ACME | H5: AD | I5: Amber | K5: awright10@acme.com | M5: 0 | P5: 42298 | R5: false | S5: false | T5: 0 | U5: true | V5: false | W5: false | X5: false | AC5: AD_mail_mail | AD5: AD_mail_mail | AE5: AD_mail_mail | AF5: 44774 | AG5: ID0000738 | AH5: Amber WRIGHT | AI5: Amber | AJ5: WRIGHT | AK5: 1 | AL5: true | AM5: awright10@acme.com | AN5: 38085 | AP5: true | AQ5: true | AR5: 16 | AS5: 3 | AT5: 7 | BG5: 15 | BH5: 0 | BI5: 7
A6: New | B6: Booking | C6: CN=Brenda SUMMERS,OU=Users,OU=ACME,DC=acme,DC=corp | D6: BSUMMERS20 | E6: Brenda SUMMERS | F6: ACME | G6: ACME | H6: AD | I6: Brenda | K6: bsummers20@acme.com | M6: 0 | P6: 42298 | R6: false | S6: false | T6: 0 | U6: false | V6: true | W6: false | X6: false | AC6: AD_mail_mail | AD6: AD_mail_mail | AE6: AD_mail_mail | AF6: 44774 | AG6: ID0000619 | AH6: Brenda SUMMERS | AI6: Brenda | AJ6: SUMMERS | AK6: 1 | AL6: true | AM6: bsummers20@acme.com | AN6: 40859 | AP6: true | AQ6: true | AR6: 18 | AS6: 3 | AT6: 5 | BG6: 6 | BH6: 0 | BI6: 16
A7: New | B7: Booking | C7: CN=Celia HOPKINS,OU=Users,OU=ACME,DC=acme,DC=corp | D7: CHOPKINS10 | E7: Celia HOPKINS | F7: ACME | G7: ACME | H7: AD | I7: Celia | K7: chopkins10@acme.com | M7: 0 | P7: 42298 | R7: false | S7: false | T7: 0 | U7: true | V7: false | W7: false | X7: false | AC7: AD_mail_mail | AD7: AD_mail_mail | AE7: AD_mail_mail | AF7: 44774 | AG7: ID0000654 | AH7: Celia HOPKINS | AI7: Celia | AJ7: HOPKINS | AK7: 1 | AL7: true | AM7: chopkins10@acme.com | AN7: 39723 | AP7: true | AQ7: true | AR7: 16 | AS7: 3 | AT7: 7 | BG7: 15 | BH7: 0 | BI7: 7
A8: Modified | B8: EPVUser | C8: CN=Desiree FLOWERS,OU=Users,OU=ACME,DC=acme,DC=corp | D8: DFLOWERS16 | E8: Desiree FLOWERS | F8: ACME | G8: ACME | H8: AD | I8: Desiree | M8: 0 | P8: 42298 | R8: false | S8: false | T8: 0 | U8: true | V8: false | W8: false | X8: false | AC8: AD_name_login | AD8: AD_name_login | AE8: AD_name_login | AF8: 44774 | AG8: ID0000832 | AH8: Desiree FLOWERS | AI8: Desiree | AJ8: FLOWERS | AK8: 1 | AL8: true | AM8: dflowers16@acme.com | AN8: 39749 | AP8: true | AQ8: true | AR8: 18 | AS8: 3 | AT8: 5 | BG8: 8 | BH8: 0 | BI8: 3
A9: New | B9: Booking | C9: CN=Dustin HARDY,OU=Users,OU=ACME,DC=acme,DC=corp | D9: DHARDY12 | E9: Dustin HARDY | F9: ACME | G9: ACME | H9: AD | I9: Dustin | K9: dhardy12@acme.com | M9: 0 | P9: 42298 | R9: false | S9: false | T9: 0 | U9: false | V9: true | W9: false | X9: false | AC9: AD_mail_mail | AD9: AD_mail_mail | AE9: AD_mail_mail | AF9: 44774 | AG9: ID0000271 | AH9: Dustin HARDY | AI9: Dustin | AJ9: HARDY | AK9: 1 | AL9: true | AM9: dhardy12@acme.com | AN9: 43526 | AP9: true | AQ9: true | AR9: 16 | AS9: 3 | AT9: 7 | BG9: 15 | BH9: 0 | BI9: 3
A10: Identical | B10: Booking | C10: CN=Dustin KNIGHT,OU=Users,OU=ACME,DC=acme,DC=corp | D10: DKNIGHT | E10: Dustin KNIGHT | F10: ACME | G10: ACME | H10: AD | I10: Dustin | K10: dknight20@acme.com | M10: 0 | P10: 42298 | R10: false | S10: false | T10: 0 | U10: true | V10: false | W10: false | X10: false | AC10: AD_mail_mail | AD10: AD_mail_mail | AE10: AD_mail_mail | AF10: 44774 | AG10: ID0000097 | AH10: Dustin KNIGHT | AI10: Dustin | AJ10: KNIGHT | AK10: 1 | AL10: true | AM10: dknight20@acme.com | AN10: 43802 | AP10: true | AQ10: true | AR10: 16 | AS10: 3 | AT10: 7 | AU10: 15 | AV10: 14 | AW10: 5 | AX10: 9 | AY10: 14 | AZ10: 55 | BA10: 309 | BB10: 254 | BC10: 82 | BD10: 49 | BE10: 59 | BF10: 5 | BG10: 15 | BH10: 0 | BI10: 12
A11: New | B11: AIMAccount | C11: CN=Ed SANTIAGO,OU=Users,OU=ACME,DC=acme,DC=corp | D11: ESANTIAG16 | E11: Ed SANTIAGO | F11: ACME | G11: ACME | H11: AD | I11: Ed | K11: esantiag16@acme.com | M11: 0 | P11: 42298 | R11: false | S11: false | T11: 0 | U11: true | V11: false | W11: false | X11: false | AC11: AD_mail_mail | AD11: AD_mail_mail | AE11: AD_mail_mail | AF11: 44774 | AG11: ID0000071 | AH11: Ed SANTIAGO | AI11: Ed | AJ11: SANTIAGO | AK11: 1 | AL11: true | AM11: esantiag16@acme.com | AN11: 40411 | AP11: true | AQ11: true | AR11: 16 | AS11: 3 | AT11: 7 | BG11: 1 | BH11: 0 | BI11: 10
A12: New | B12: AIMAccount | C12: CN=Emmett CRAWFORD,OU=Users,OU=ACME,DC=acme,DC=corp | D12: ECRAWFOR13 | E12: Emmett CRAWFORD | F12: ACME | G12: ACME | H12: AD | I12: Emmett | K12: ecrawfor13@acme.com | M12: 0 | P12: 42298 | R12: false | S12: false | T12: 0 | U12: true | V12: false | W12: false | X12: false | AC12: AD_mail_mail | AD12: AD_mail_mail | AE12: AD_mail_mail | AF12: 44774 | AG12: ID0000529 | AH12: Emmett CRAWFORD | AI12: Emmett | AJ12: CRAWFORD | AK12: 1 | AL12: true | AM12: ecrawfor13@acme.com | AN12: 37181 | AP12: true | AQ12: true | AR12: 16 | AS12: 3 | AT12: 7 | BG12: 15 | BH12: 0 | BI12: 2
A13: New | B13: AIMAccount | C13: CN=Enrique WILKERSON,OU=Users,OU=ACME,DC=acme,DC=corp | D13: EWILKERS12 | E13: Enrique WILKERSON | F13: ACME | G13: ACME | H13: AD | I13: Enrique | K13: ewilkers12@acme.com | M13: 0 | P13: 42298 | R13: false | S13: false | T13: 0 | U13: true | V13: false | W13: false | X13: false | AC13: AD_mail_mail | AD13: AD_mail_mail | AE13: AD_mail_mail | AF13: 44774 | AG13: ID0000077 | AH13: Enrique WILKERSON | AI13: Enrique | AJ13: WILKERSON | AK13: 1 | AL13: true | AM13: ewilkers12@acme.com | AN13: 39969 | AP13: true | AQ13: true | AR13: 16 | AS13: 3 | AT13: 7 | BG13: 1 | BH13: 0 | BI13: 11
A14: New | B14: Booking | C14: CN=George BUCHANAN-adm,OU=Users,OU=ACME,DC=acme,DC=corp | D14: GBUCHANA-adm | E14: George BUCHANAN | F14: ACME | G14: ACME | H14: AD | I14: George | K14: gbuchana13@acme.com | M14: 0 | P14: 44521 | R14: false | S14: false | T14: 0 | U14: true | V14: false | W14: false | X14: false | AC14: AD_mail_mail | AD14: AD_mail_mail | AE14: AD_mail_mail | AF14: 44774 | AG14: ID0000079 | AH14: George BUCHANAN | AI14: George | AJ14: BUCHANAN | AK14: 1 | AL14: true | AM14: gbuchana13@acme.com | AN14: 40226 | AP14: true | AQ14: true | AR14: 16 | AS14: 3 | AT14: 7 | BG14: 15 | BH14: 0 | BI14: 1
A15: New | B15: Booking | C15: CN=Gilberto MASSEY,OU=Users,OU=ACME,DC=acme,DC=corp | D15: GMASSEY11 | E15: Gilberto MASSEY | F15: ACME | G15: ACME | H15: AD | I15: Gilberto | K15: gmassey11@acme.com | M15: 0 | P15: 42298 | R15: false | S15: false | T15: 0 | U15: false | V15: true | W15: false | X15: false | AC15: AD_mail_mail | AD15: AD_mail_mail | AE15: AD_mail_mail | AF15: 44774 | AG15: ID0000631 | AH15: Gilberto MASSEY | AI15: Gilberto | AJ15: MASSEY | AK15: 1 | AL15: true | AM15: gmassey11@acme.com | AN15: 39880 | AP15: true | AQ15: true | AR15: 15 | AS15: 3 | AT15: 9 | AU15: 16 | AV15: 15 | AW15: 6 | AX15: 10 | AY15: 14 | AZ15: 57 | BA15: 333 | BB15: 276 | BC15: 106 | BD15: 51 | BE15: 81 | BF15: 6 | BG15: 15 | BH15: 0 | BI15: 11
A16: Modified | B16: Booking | C16: CN=Howard BELL,OU=Users,OU=ACME,DC=acme,DC=corp | D16: HBELL11 | E16: Howard BELL | F16: ACME | G16: ACME | H16: AD | I16: Howard | M16: 0 | P16: 42298 | R16: false | S16: false | T16: 0 | U16: false | V16: true | W16: false | X16: false | AC16: AD_name_login | AD16: AD_name_login | AE16: AD_name_login | AF16: 44774 | AG16: ID0000605 | AH16: Howard BELL | AI16: Howard | AJ16: BELL | AK16: 1 | AL16: true | AM16: hbell11@acme.com | AN16: 40225 | AP16: true | AQ16: true | AR16: 13 | AS16: 3 | AT16: 11 | AU16: 35 | AV16: 14 | AW16: 16 | AX16: 28 | AY16: 27 | AZ16: 59 | BA16: 369 | BB16: 310 | BC16: 109 | BD16: 53 | BE16: 80 | BF16: 5 | BG16: 19 | BH16: 0 | BI16: 2
A17: Identical | B17: Booking | C17: CN=Jaime ROBERTSON,OU=Users,OU=ACME,DC=acme,DC=corp | D17: JROBERTS19 | E17: Jaime ROBERTSON | F17: ACME | G17: ACME | H17: AD | I17: Jaime | K17: jroberts19@acme.com | M17: 0 | P17: 42298 | R17: false | S17: false | T17: 0 | U17: true | V17: false | W17: false | X17: false | AC17: AD_mail_mail | AD17: AD_mail_mail | AE17: AD_mail_mail | AF17: 44774 | AG17: ID0000709 | AH17: Jaime ROBERTSON | AI17: Jaime | AJ17: ROBERTSON | AK17: 1 | AL17: true | AM17: jroberts19@acme.com | AN17: 40505 | AP17: true | AQ17: true | AR17: 16 | AS17: 3 | AT17: 7 | AU17: 15 | AV17: 14 | AW17: 5 | AX17: 9 | AY17: 14 | AZ17: 55 | BA17: 309 | BB17: 254 | BC17: 82 | BD17: 49 | BE17: 59 | BF17: 5 | BG17: 15 | BH17: 0 | BI17: 13
A18: New | B18: Booking | C18: CN=Kara AGUILAR,OU=Users,OU=ACME,DC=acme,DC=corp | D18: KAGUILAR14 | E18: Kara AGUILAR | F18: ACME | G18: ACME | H18: AD | I18: Kara | K18: kaguilar14@acme.com | M18: 0 | P18: 42298 | R18: false | S18: false | T18: 0 | U18: true | V18: false | W18: false | X18: false | AC18: AD_mail_mail | AD18: AD_mail_mail | AE18: AD_mail_mail | AF18: 44774 | AG18: ID0000134 | AH18: Kara AGUILAR | AI18: Kara | AJ18: AGUILAR | AK18: 1 | AL18: true | AM18: kaguilar14@acme.com | AN18: 38357 | AP18: true | AQ18: true | AR18: 16 | AS18: 3 | AT18: 7 | BG18: 15 | BH18: 0 | BI18: 3
A19: New | B19: Booking | C19: CN=Karen POWELL,OU=Users,OU=ACME,DC=acme,DC=corp | D19: KPOWELL10 | E19: Karen POWELL | F19: ACME | G19: ACME | H19: AD | I19: Karen | K19: kpowell10@acme.com | M19: 0 | P19: 42298 | R19: false | S19: false | T19: 0 | U19: true | V19: false | W19: false | X19: false | AC19: AD_mail_mail | AD19: AD_mail_mail | AE19: AD_mail_mail | AF19: 44774 | AG19: ID0000122 | AH19: Karen POWELL | AI19: Karen | AJ19: POWELL | AK19: 1 | AL19: true | AM19: kpowell10@acme.com | AN19: 40903 | AP19: true | AQ19: true | AR19: 15 | AS19: 3 | AT19: 9 | AU19: 16 | AV19: 15 | AW19: 6 | AX19: 10 | AY19: 14 | AZ19: 57 | BA19: 333 | BB19: 276 | BC19: 106 | BD19: 51 | BE19: 81 | BF19: 6 | BG19: 15 | BH19: 0 | BI19: 48
A20: New | B20: Booking | C20: CN=Katie MCDANIEL,OU=Users,OU=ACME,DC=acme,DC=corp | D20: KMCDANIE16 | E20: Katie MCDANIEL | F20: ACME | G20: ACME | H20: AD | I20: Katie | K20: kmcdanie16@acme.com | M20: 0 | P20: 42298 | R20: false | S20: false | T20: 0 | U20: true | V20: false | W20: false | X20: false | AA20: leave | AB20: 44774 | AC20: AD_mail_mail | AD20: identity is not working any more for the company today | AE20: Katie MCDANIEL (ID0000966) | AF20: 44774 | AP20: true | AQ20: true | AR20: 3 | AS20: 4 | AT20: 11 | AU20: 24 | AV20: 21 | AW20: 10 | AX20: 20 | AY20: 23 | AZ20: 103 | BA20: 716 | BB20: 613 | BC20: 179 | BD20: 87 | BE20: 139 | BF20: 7 | BG20: 15 | BH20: 0 | BI20: 10
A21: New | B21: Booking | C21: CN=Ken MEYER,OU=Users,OU=ACME,DC=acme,DC=corp | D21: KMEYER19 | E21: Ken MEYER | F21: ACME | G21: ACME | H21: AD | I21: Ken | K21: kmeyer19@acme.com | M21: 0 | P21: 42298 | R21: false | S21: false | T21: 0 | U21: true | V21: false | W21: false | X21: false | AC21: AD_mail_mail | AD21: AD_mail_mail | AE21: AD_mail_mail | AF21: 44774 | AG21: ID0000067 | AH21: Ken MEYER | AI21: Ken | AJ21: MEYER | AK21: 1 | AL21: true | AM21: kmeyer19@acme.com | AN21: 40758 | AP21: true | AQ21: true | AR21: 18 | AS21: 3 | AT21: 5 | BG21: 6 | BH21: 0 | BI21: 17
A22: New | B22: Booking | C22: CN=Kerry GARRETT,OU=Users,OU=ACME,DC=acme,DC=corp | D22: KGARRETT10 | E22: Kerry GARRETT | F22: ACME | G22: ACME | H22: AD | I22: Kerry | K22: kgarrett10@acme.com | M22: 0 | P22: 42298 | R22: false | S22: false | T22: 0 | U22: true | V22: false | W22: false | X22: false | AC22: AD_mail_mail | AD22: AD_mail_mail | AE22: AD_mail_mail | AF22: 44774 | AG22: ID0001000 | AH22: Kerry GARRETT | AI22: Kerry | AJ22: GARRETT | AL22: true | AM22: kgarrett10@acme.com | AN22: 37240 | AP22: true | AQ22: true | AR22: 18 | AS22: 3 | AT22: 5 | BG22: 8 | BH22: 0 | BI22: 5
A23: New | B23: Booking | C23: CN=Meghan CANNON,OU=Users,OU=ACME,DC=acme,DC=corp | D23: MCANNON18 | E23: Meghan CANNON | F23: ACME | G23: ACME | H23: AD | I23: Meghan | K23: mcannon18@acme.com | M23: 0 | P23: 42298 | R23: false | S23: false | T23: 0 | U23: true | V23: false | W23: false | X23: false | AC23: AD_mail_mail | AD23: AD_mail_mail | AE23: AD_mail_mail | AF23: 44774 | AG23: ID0000794 | AH23: Meghan CANNON | AI23: Meghan | AJ23: CANNON | AK23: 0 | AL23: true | AM23: mcannon18@acme.com | AN23: 44142 | AP23: true | AQ23: true | AR23: 2 | AS23: 4 | AT23: 13 | BG23: 19 | BH23: 0 | BI23: 5
A24: Modified | B24: Booking | C24: CN=Melba MCGUIRE,OU=Users,OU=ACME,DC=acme,DC=corp | D24: MMCGUIRE16 | E24: Melba MCGUIRE | F24: ACME | G24: ACME | H24: AD | I24: Melba | M24: 0 | P24: 42298 | R24: false | S24: false | T24: 0 | U24: false | V24: true | W24: false | X24: false | AC24: AD_name_login | AD24: AD_name_login | AE24: AD_name_login | AF24: 44774 | AG24: ID0000804 | AH24: Melba MCGUIRE | AI24: Melba | AJ24: MCGUIRE | AK24: 1 | AL24: true | AM24: mmcguire16@acme.com | AN24: 37005 | AP24: true | AQ24: true | AR24: 14 | AS24: 3 | AT24: 11 | AU24: 20 | AV24: 13 | AW24: 9 | AX24: 14 | AY24: 16 | AZ24: 83 | BA24: 598 | BB24: 515 | BC24: 143 | BD24: 68 | BE24: 117 | BF24: 7 | BG24: 8 | BH24: 0 | BI24: 3
A25: Modified | B25: Booking | C25: CN=Melissa BALL,OU=Users,OU=ACME,DC=acme,DC=corp | D25: MBALL13 | E25: Melissa BALL | F25: ACME | G25: ACME | H25: AD | I25: Melissa | K25: mball13@acme.com | M25: 0 | P25: 42298 | R25: false | S25: false | T25: 0 | U25: true | V25: false | W25: false | X25: false | AC25: AD_mail_mail | AD25: AD_mail_mail | AE25: AD_mail_mail | AF25: 44774 | AG25: ID0000560 | AH25: Melissa BALL | AI25: Melissa | AJ25: BALL | AK25: 1 | AL25: true | AM25: mball13@acme.com | AN25: 37343 | AP25: true | AQ25: true | AR25: 13 | AS25: 3 | AT25: 11 | AU25: 53 | AV25: 22 | AW25: 28 | AX25: 41 | AY25: 38 | AZ25: 109 | BA25: 713 | BB25: 604 | BC25: 218 | BD25: 94 | BE25: 165 | BF25: 6 | BG25: 19 | BH25: 0 | BI25: 23
A26: New | B26: Booking | C26: CN=Neil REED,OU=Users,OU=ACME,DC=acme,DC=corp | D26: NREED10 | E26: Neil REED | F26: ACME | G26: ACME | H26: AD | I26: Neil | M26: 0 | P26: 42298 | R26: false | S26: false | T26: 0 | U26: true | V26: false | W26: false | X26: false | AA26: leave | AB26: 44774 | AC26: AD_name_login | AD26: identity is not working any more for the company today | AE26: Neil REED (ID0000935) | AF26: 44774 | AP26: true | AQ26: true | AR26: 4 | AS26: 4 | AT26: 6 | BG26: 8 | BH26: 0 | BI26: 5
A27: New | B27: Booking | C27: CN=Orlando FULLER,OU=Users,OU=ACME,DC=acme,DC=corp | D27: OFULLER16 | E27: Orlando FULLER | F27: ACME | G27: ACME | H27: AD | I27: Orlando | K27: OFULLER16@acme.com | M27: 0 | P27: 42298 | R27: false | S27: false | T27: 0 | U27: false | V27: true | W27: false | X27: false | AC27: AD_mail_mail | AD27: AD_mail_mail | AE27: AD_mail_mail | AF27: 44774 | AG27: ID0000087 | AH27: Orlando FULLER | AI27: Orlando | AJ27: FULLER | AK27: 1 | AL27: true | AM27: ofuller16@acme.com | AN27: 42157 | AP27: false | AQ27: true | AR27: 16 | AS27: 3 | AT27: 7 | BG27: 1 | BH27: 0 | BI27: 1
A28: New | B28: Test | C28: CN=Philip HOPKINS,OU=Users,OU=ACME,DC=acme,DC=corp | D28: PHOPKINS15 | E28: Philip HOPKINS | F28: ACME | G28: ACME | H28: AD | I28: Philip | M28: 0 | P28: 42298 | R28: false | S28: false | T28: 0 | U28: true | V28: false | W28: false | X28: false | AC28: AD_name_login | AD28: AD_name_login | AE28: AD_name_login | AF28: 44774 | AG28: ID0000825 | AH28: Philip HOPKINS | AI28: Philip | AJ28: HOPKINS | AK28: 1 | AL28: true | AM28: phopkins15@acme.com | AN28: 38429 | AP28: true | AQ28: true | AR28: 16 | AS28: 3 | AT28: 7 | BG28: 15 | BH28: 0 | BI28: 2
A29: New | B29: Booking | C29: CN=Sadie PIERCE,OU=Users,OU=ACME,DC=acme,DC=corp | D29: SPIERCE18 | E29: Sadie PIERCE | F29: ACME | G29: ACME | H29: AD | I29: Sadie | K29: spierce18@acme.com | M29: 0 | P29: 42298 | R29: false | S29: false | T29: 0 | U29: true | V29: false | W29: false | X29: false | AC29: AD_mail_mail | AD29: AD_mail_mail | AE29: AD_mail_mail | AF29: 44774 | AG29: ID0000058 | AH29: Sadie PIERCE | AI29: Sadie | AJ29: PIERCE | AK29: 1 | AL29: true | AM29: spierce18@acme.com | AN29: 36894 | AP29: true | AQ29: true | AR29: 16 | AS29: 3 | AT29: 7 | BG29: 1 | BH29: 0 | BI29: 8
A30: New | B30: Booking | C30: CN=Steven MURPHY,OU=Users,OU=ACME,DC=acme,DC=corp | D30: SMURPHY16 | E30: Steven MURPHY | F30: ACME | G30: ACME | H30: AD | I30: Steven | K30: smurphy16@acme.com | M30: 0 | P30: 42298 | R30: false | S30: false | T30: 0 | U30: true | V30: false | W30: false | X30: false | AA30: leave | AB30: 44774 | AC30: AD_mail_mail | AD30: identity is not working any more for the company today | AE30: Steven MURPHY (ID0000991) | AF30: 44774 | AP30: true | AQ30: true | AR30: 4 | AS30: 4 | AT30: 6 | BG30: 8 | BH30: 0 | BI30: 4
A31: New | B31: Booking | C31: CN=Sylvia QUINN,OU=Users,OU=ACME,DC=acme,DC=corp | D31: SQUINN20 | E31: Sylvia QUINN | F31: ACME | G31: ACME | H31: AD | I31: Sylvia | M31: 0 | P31: 42298 | R31: false | S31: false | T31: 0 | U31: true | V31: false | W31: false | X31: false | AC31: AD_name_login | AD31: AD_name_login | AE31: AD_name_login | AF31: 44774 | AG31: ID0000154 | AH31: Sylvia QUINN | AI31: Sylvia | AJ31: QUINN | AK31: 1 | AL31: true | AM31: squinn20@acme.com | AN31: 39980 | AP31: true | AQ31: true | AR31: 18 | AS31: 3 | AT31: 5 | BG31: 8 | BH31: 0 | BI31: 6
A32: Modified | B32: Test | C32: CN=Tonya HENDERSON,OU=Users,OU=ACME,DC=acme,DC=corp | D32: THENDERS13 | E32: Tonya HENDERSON | F32: ACME | G32: ACME | H32: AD | I32: Tonya | K32: thenders13@acme.com | M32: 0 | P32: 42298 | R32: false | S32: false | T32: 0 | U32: true | V32: false | W32: false | X32: false | AA32: leave | AB32: 44774 | AC32: AD_mail_mail | AD32: identity is not working any more for the company today | AE32: Tonya HENDERSON (ID0000934) | AF32: 44774 | AP32: true | AQ32: true | AR32: 4 | AS32: 4 | AT32: 6 | BG32: 8 | BH32: 0 | BI32: 3
A33: Modified | B33: Booking | C33: CN=Tracy CURTIS,OU=Users,OU=ACME,DC=acme,DC=corp | D33: TCURTIS12 | E33: Tracy CURTIS | F33: ACME | G33: ACME | H33: AD | I33: Tracy | M33: 0 | P33: 42298 | R33: false | S33: false | T33: 0 | U33: false | V33: true | W33: false | X33: false | AP33: true | AQ33: true | AR33: 16 | AS33: 3 | AT33: 7 | BG33: 8 | BH33: 0 | BI33: 4
A34: New | B34: Booking | C34: CN=Viola ROBERTS,OU=Users,OU=ACME,DC=acme,DC=corp | D34: VROBERTS16 | E34: Viola ROBERTS | F34: ACME | G34: ACME | H34: AD | I34: Viola | K34: VROBERTS16@acme.com | M34: 0 | P34: 42298 | R34: false | S34: false | T34: 0 | U34: false | V34: true | W34: false | X34: false | AC34: AD_mail_mail | AD34: AD_mail_mail | AE34: AD_mail_mail | AF34: 44774 | AG34: ID0000086 | AH34: Viola ROBERTS | AI34: Viola | AJ34: ROBERTS | AK34: 1 | AL34: true | AM34: vroberts16@acme.com | AN34: 43198 | AP34: false | AQ34: true | AR34: 16 | AS34: 3 | AT34: 7 | BG34: 1 | BH34: 0 | BI34: 1
A35: New | B35: Booking | C35: CN=Willie COPELAND,OU=Users,OU=ACME,DC=acme,DC=corp | D35: WCOPELAN14 | E35: Willie COPELAND | F35: ACME | G35: ACME | H35: AD | I35: Willie | K35: wcopelan14@acme.com | M35: 0 | P35: 42298 | R35: false | S35: false | T35: 0 | U35: true | V35: false | W35: false | X35: false | AC35: AD_mail_mail | AD35: AD_mail_mail | AE35: AD_mail_mail | AF35: 44774 | AG35: ID0000694 | AH35: Willie COPELAND | AI35: Willie | AJ35: COPELAND | AK35: 1 | AL35: true | AM35: wcopelan14@acme.com | AN35: 38742 | AP35: true | AQ35: true | AR35: 18 | AS35: 3 | AT35: 6 | AU35: 25 | AV35: 22 | AW35: 11 | AX35: 20 | AY35: 22 | AZ35: 100 | BA35: 735 | BB35: 635 | BC35: 198 | BD35: 84 | BE35: 161 | BF35: 7 | BG35: 6 | BH35: 0 | BI35: 24
A36: Removed | B36: Booking | C36: CN=Tasha PATTERSON,OU=Users,OU=ACME,DC=acme,DC=corp | D36: TPATTERS20 | E36: Tasha PATTERSON | F36: ACME | G36: ACME | H36: AD | I36: Tasha | K36: tpatters20@acme.com | M36: 0 | P36: 42298 | R36: false | S36: false | T36: 0 | U36: false | V36: true | W36: false | X36: false | AC36: AD_name_login | AD36: AD_name_login | AE36: AD_name_login | AF36: 44774 | AH36: Tasha PATTERSON | AI36: Tasha | AJ36: PATTERSON | AK36: 0 | AL36: true | AM36: tpatters19@acme.com | AP36: false | AQ36: true | AR36: 2 | AS36: 4 | AT36: 9 | AU36: 13 | AV36: 12 | AW36: 5 | AX36: 9 | AY36: 12 | AZ36: 70 | BA36: 448 | BB36: 378 | BC36: 112 | BD36: 58 | BE36: 86 | BF36: 6 | BH36: 0 | BI36: 1
A37: Removed | B37: Booking | C37: CN=Dominic WOLFE,OU=Users,OU=ACME,DC=acme,DC=corp | D37: dwolfe20 | E37: Dominic WOLFE | F37: ACME | G37: ACME | H37: AD | I37: Dominic | K37: dwolfe20@acme.com | M37: 0 | P37: 42298 | R37: false | S37: false | T37: 0 | U37: false | V37: true | W37: false | X37: false | AC37: AD_mail_mail | AD37: AD_mail_mail | AE37: AD_mail_mail | AF37: 44774 | AH37: Dominic WOLFE | AI37: Dominic | AJ37: WOLFE | AK37: 0 | AL37: true | AM37: dwolfe20@acme.com | AP37: false | AQ37: true | AR37: 2 | AS37: 4 | AT37: 9 | AU37: 13 | AV37: 12 | AW37: 5 | AX37: 9 | AY37: 12 | AZ37: 70 | BA37: 448 | BB37: 378 | BC37: 112 | BD37: 58 | BE37: 86 | BF37: 6 | BH37: 0 | BI37: 1
A38: Removed | B38: Booking | C38: CN=Lance KNIGHT,OU=Users,OU=ACME,DC=acme,DC=corp | D38: LKNIGHT36 | E38: Lance KNIGHT | F38: ACME | G38: ACME | H38: AD | I38: Lance | M38: 0 | P38: 42298 | R38: false | S38: false | T38: 0 | U38: false | V38: true | W38: false | X38: false | AP38: false | AQ38: true | AR38: 10 | AS38: 3 | AT38: 8 | AU38: 13 | AV38: 12 | AW38: 5 | AX38: 9 | AY38: 12 | AZ38: 70 | BA38: 448 | BB38: 378 | BC38: 112 | BD38: 58 | BE38: 86 | BF38: 6 | BH38: 0 | BI38: 1
A39: users

Sheet groups
A1: status | B1: group_displayname | C1: group_bwa_groupmetadata_descr | D1: group_code | E1: group_sid | F1: group_guid | G1: group_comment | H1: group_modificationdate | I1: group_creationdate | J1: group_dynamic | K1: group_lastmodifiedby | L1: group_bwa_groupmetadata_sensitivitylevel | M1: group_bwa_groupmetadata_sensitivityreason | N1: nb_child_groups | O1: group_bwa_groupanalytics_nbaccount | P1: group_bwa_groupanalytics_nbdirectaccount | Q1: group_bwa_groupanalytics_nbidentity | R1: group_bwa_groupanalytics_nbdirectidentity | S1: nb_contractors | T1: nb_organizations | U1: nb_safes | V1: nb_direct_safes | W1: nb_vaults | X1: nb_credentials | Y1: nb_credentials_no_cpm | Z1: nb_platforms | AA1: nb_resources | AB1: nb_permission
A2: Modified | B2: TechGroup | D2: CN=TechGroup,OU=Users,OU=ACME,DC=acme,DC=corp | E2: S-1-5-21-2198405017-3190945858-2291852294-1902 | F2: b42e045e-cbc8-459f-9850-3d01045c792b | H2: 42298 | I2: 42298 | J2: false | N2: 0 | O2: 0 | P2: 0 | Q2: 0 | R2: 0 | S2: 0 | T2: 0 | U2: 12 | V2: 12 | W2: 2 | X2: 379 | Y2: 50 | Z2: 4 | AA2: 111 | AB2: 18
A3: New | B3: Finance CyberArk Safes Users | D3: CN=Finance CyberArk Safes Users,CN=Builtin,DC=acme,DC=corp | E3: S-3-7-34-548 | F3: ed815fd8-66b2-4352-922a-3364cca6cbb7 | G3: Members can administer Finance infrastructure | H3: 44490 | I3: 44639 | J3: false | N3: 0 | O3: 4 | P3: 4 | Q3: 2 | R3: 2 | S3: 0 | T3: 2 | U3: 14 | V3: 0 | W3: 0 | X3: 594 | Y3: 83 | Z3: 6 | AA3: 139 | AB3: 8
A4: Modified | B4: Finance Account Operators | D4: CN=Finance Account Operators,CN=Builtin,DC=acme,DC=corp | E4: S-1-5-32-548 | F4: ed815fd7-66b2-4352-862a-2264cca6cbb7 | G4: Members can administer finance user and group accounts | H4: 42298 | I4: 42296 | J4: false | L4: 4 | N4: 1 | O4: 3 | P4: 0 | Q4: 3 | R4: 0 | S4: 0 | T4: 0 | U4: 14 | V4: 14 | W4: 0 | X4: 566 | Y4: 76 | Z4: 4 | AA4: 148 | AB4: 6
A5: New | B5: Finance CyberArk Safes Admin | D5: CN=Finance CyberArk Safes Admin,CN=Builtin,DC=acme,DC=corp | E5: S-2-8-32-549 | F5: ed915fd7-66b2-4353-878a-2264cca6cbb7 | G5: Members can administer CyberArk safes containing Finance infrastructure secrets | H5: 44490 | I5: 44490 | J5: false | N5: 0 | O5: 3 | P5: 3 | Q5: 3 | R5: 3 | S5: 0 | T5: 3 | U5: 14 | V5: 0 | W5: 0 | X5: 566 | Y5: 76 | Z5: 4 | AA5: 148 | AB5: 6
A6: New | B6: Quality-Admin | D6: CN=Quality-Admin,OU=Users,OU=ACME,DC=acme,DC=corp | E6: S-1-5-21-2198405017-3190945858-2291852294-1961 | F6: 16623444-0239-43d9-8aef-e2de64c9dde7 | H6: 42298 | I6: 42298 | J6: false | N6: 0 | O6: 4 | P6: 4 | Q6: 3 | R6: 3 | S6: 0 | T6: 2 | U6: 15 | V6: 0 | W6: 2 | X6: 309 | Y6: 55 | Z6: 5 | AA6: 82 | AB6: 15
A7: Modified | B7: Finance Server Administrators | D7: CN=Finance Server Administrators,OU=Users,OU=ACME,DC=acme,DC=corp | E7: S-1-5-21-2198405017-3190945858-2291852294-2116 | F7: b8e3c465-442e-447c-b6c3-29e98f6b1878 | G7: Windows Production Servers for Finance Application Administration Group | H7: 42298 | I7: 42298 | J7: false | N7: 1 | O7: 8 | P7: 4 | Q7: 4 | R7: 2 | S7: 0 | T7: 2 | U7: 14 | V7: 14 | W7: 0 | X7: 594 | Y7: 83 | Z7: 6 | AA7: 139 | AB7: 8
A8: Modified | B8: EU-IT_tools | D8: CN=EU-IT_tools,OU=Users,OU=ACME,DC=acme,DC=corp | E8: S-1-5-21-2198405017-3190945858-2291852294-2118 | F8: a6aeef41-bfec-46a2-9aa3-919fbf5aba69 | H8: 42298 | I8: 42298 | J8: false | N8: 0 | O8: 4 | P8: 4 | Q8: 4 | R8: 4 | S8: 1 | T8: 4 | U8: 16 | V8: 16 | W8: 2 | X8: 358 | Y8: 58 | Z8: 4 | AA8: 98 | AB8: 19
A9: New | B9: MarketArea-Europe | D9: CN=MarketArea-Europe,OU=Groups,OU=ACME,DC=acme,DC=corp | E9: S-1-5-33-2198405017-3190222258-2291852294-1963 | F9: 2d7e1444-95aa-4baa-9b22-f40415ba9f49 | G9: Europe Market Area Team | H9: 42298 | I9: 42298 | J9: false | N9: 0 | O9: 5 | P9: 5 | Q9: 5 | R9: 5 | S9: 0 | T9: 1 | U9: 14 | V9: 0 | W9: 2 | X9: 449 | Y9: 73 | Z9: 4 | AA9: 133 | AB9: 1
A10: Identical | B10: EU-Research-Dev | D10: CN=EU-Research-Dev,OU=Users,OU=ACME,DC=acme,DC=corp | E10: S-1-5-21-2198405017-3190945858-2291852294-2013 | F10: 2d0228c6-9bc6-4dcc-8766-783508a1e58f | H10: 42298 | I10: 42298 | J10: false | N10: 1 | O10: 8 | P10: 3 | Q10: 7 | R10: 2 | S10: 0 | T10: 2 | U10: 14 | V10: 14 | W10: 2 | X10: 449 | Y10: 73 | Z10: 4 | AA10: 133 | AB10: 1
A11: Identical | B11: EMEA-ADMIN | D11: CN=EMEA-ADMIN,OU=EMEA,OU=N3,OU=N2,OU=N1,DC=acme,DC=corp | E11: S-1-5-50-544 | F11: c1f73e58-fb50-407c-84e8-8ffdff891539 | G11: CyberArk group | H11: 42298 | I11: 42296 | J11: false | N11: 1 | O11: 12 | P11: 8 | Q11: 11 | R11: 8 | S11: 0 | T11: 6 | U11: 15 | V11: 15 | W11: 2 | X11: 309 | Y11: 55 | Z11: 5 | AA11: 82 | AB11: 15
A12: groups

Sheet credentials
A1: status | B1: credential | C1: cred_username | D1: cred_address | E1: cred_platformid | F1: cred_secrettype | G1: cred_automaticmanagement_enabled | H1: cred_managementstatus | I1: cred_manualmanagement_reason | J1: cred_lastverifiedtime | K1: cred_lastreconciledtime | L1: cred_code | M1: safe_displayname | N1: safe_code | O1: safe_description | P1: vault_displayname | Q1: nb_users | R1: nb_epv_users | S1: nb_app_users | T1: nb_other_users | U1: nb_builtin_users | V1: nb_groups | W1: nb_identities | X1: nb_contractors | Y1: nb_organizations
A2: Modified | B2: operator@al-svr-qa-9369.roberts-parker.com | C2: operator | D2: al-svr-qa-9369.roberts-parker.com | E2: WinDesktopLocal | F2: password | G2: 1 | H2: failed | L2: 127_684_EXTERNAL-VAULT | M2: Laptops | N2: Laptops_EXTERNAL-VAULT | O2: Credentials for Laptops | P2: EXTERNAL-VAULT | Q2: 34 | R2: 12 | S2: 0 | T2: 0 | U2: 0 | V2: 10 | W2: 28 | X2: 1 | Y2: 18
A3: Modified | B3: qa@al-svr-qa-9369.roberts-parker.com | C3: qa | D3: al-svr-qa-9369.roberts-parker.com | E3: WinDesktopLocal | F3: password | G3: 1 | H3: failed | L3: 127_680_EXTERNAL-VAULT | M3: Laptops | N3: Laptops_EXTERNAL-VAULT | O3: Credentials for Laptops | P3: EXTERNAL-VAULT | Q3: 34 | R3: 12 | S3: 0 | T3: 0 | U3: 0 | V3: 10 | W3: 28 | X3: 1 | Y3: 18
A4: Modified | B4: run_ops_level_02@al-svr-qa-9369.roberts-parker.com | C4: run_ops_level_02 | D4: al-svr-qa-9369.roberts-parker.com | E4: WinDesktopLocal | F4: password | G4: 1 | H4: failed | L4: 127_682_EXTERNAL-VAULT | M4: Laptops | N4: Laptops_EXTERNAL-VAULT | O4: Credentials for Laptops | P4: EXTERNAL-VAULT | Q4: 34 | R4: 12 | S4: 0 | T4: 0 | U4: 0 | V4: 10 | W4: 28 | X4: 1 | Y4: 18
A5: Modified | B5: _report_@hn-esx-prd-6568.roberts-parker.com | C5: _report_ | D5: hn-esx-prd-6568.roberts-parker.com | E5: WinDesktopLocal | F5: password | G5: 1 | H5: failed | L5: 127_643_EXTERNAL-VAULT | M5: Laptops | N5: Laptops_EXTERNAL-VAULT | O5: Credentials for Laptops | P5: EXTERNAL-VAULT | Q5: 34 | R5: 12 | S5: 0 | T5: 0 | U5: 0 | V5: 10 | W5: 28 | X5: 1 | Y5: 18
A6: Modified | B6: Administrator@hn-esx-prd-6568.roberts-parker.com | C6: Administrator | D6: hn-esx-prd-6568.roberts-parker.com | E6: WinDesktopLocal | F6: password | G6: 1 | H6: failed | L6: 127_638_EXTERNAL-VAULT | M6: Laptops | N6: Laptops_EXTERNAL-VAULT | O6: Credentials for Laptops | P6: EXTERNAL-VAULT | Q6: 34 | R6: 12 | S6: 0 | T6: 0 | U6: 0 | V6: 10 | W6: 28 | X6: 1 | Y6: 18
A7: Modified | B7: dba@lt-esx-dev-9197.roberts-parker.com | C7: dba | D7: lt-esx-dev-9197.roberts-parker.com | E7: WinDesktopLocal | F7: password | G7: 1 | H7: failed | L7: 127_633_EXTERNAL-VAULT | M7: Laptops | N7: Laptops_EXTERNAL-VAULT | O7: Credentials for Laptops | P7: EXTERNAL-VAULT | Q7: 34 | R7: 12 | S7: 0 | T7: 0 | U7: 0 | V7: 10 | W7: 28 | X7: 1 | Y7: 18
A8: Modified | B8: dba_level_01@sr-ctx-prd-5142.roberts-parker.com | C8: dba_level_01 | D8: sr-ctx-prd-5142.roberts-parker.com | E8: WinDesktopLocal | F8: password | G8: 1 | H8: failed | L8: 127_619_EXTERNAL-VAULT | M8: Laptops | N8: Laptops_EXTERNAL-VAULT | O8: Credentials for Laptops | P8: EXTERNAL-VAULT | Q8: 34 | R8: 12 | S8: 0 | T8: 0 | U8: 0 | V8: 10 | W8: 28 | X8: 1 | Y8: 18
A9: Modified | B9: dba@to-des-prd-3745.roberts-parker.com | C9: dba | D9: to-des-prd-3745.roberts-parker.com | E9: WinDesktopLocal | F9: password | G9: 1 | H9: failed | L9: 127_662_EXTERNAL-VAULT | M9: Laptops | N9: Laptops_EXTERNAL-VAULT | O9: Credentials for Laptops | P9: EXTERNAL-VAULT | Q9: 34 | R9: 12 | S9: 0 | T9: 0 | U9: 0 | V9: 10 | W9: 28 | X9: 1 | Y9: 18
A10: Modified | B10: _svc_@ua-des-dev-3219.roberts-parker.com | C10: _svc_ | D10: ua-des-dev-3219.roberts-parker.com | E10: WinDesktopLocal | F10: password | G10: 1 | H10: failed | L10: 127_666_EXTERNAL-VAULT | M10: Laptops | N10: Laptops_EXTERNAL-VAULT | O10: Credentials for Laptops | P10: EXTERNAL-VAULT | Q10: 34 | R10: 12 | S10: 0 | T10: 0 | U10: 0 | V10: 10 | W10: 28 | X10: 1 | Y10: 18
A11: Modified | B11: root@ua-des-dev-3219.roberts-parker.com | C11: root | D11: ua-des-dev-3219.roberts-parker.com | E11: WinDesktopLocal | F11: password | G11: 1 | H11: failed | L11: 127_668_EXTERNAL-VAULT | M11: Laptops | N11: Laptops_EXTERNAL-VAULT | O11: Credentials for Laptops | P11: EXTERNAL-VAULT | Q11: 34 | R11: 12 | S11: 0 | T11: 0 | U11: 0 | V11: 10 | W11: 28 | X11: 1 | Y11: 18
A12: Modified | B12: qa@ge-svr-dev-1480.roberts-parker.com | C12: qa | D12: ge-svr-dev-1480.roberts-parker.com | E12: WinDesktopLocal | F12: password | G12: 1 | H12: inProcess | L12: 127_686_EXTERNAL-VAULT | M12: Laptops | N12: Laptops_EXTERNAL-VAULT | O12: Credentials for Laptops | P12: EXTERNAL-VAULT | Q12: 34 | R12: 12 | S12: 0 | T12: 0 | U12: 0 | V12: 10 | W12: 28 | X12: 1 | Y12: 18
A13: Modified | B13: guest@hn-esx-prd-6568.roberts-parker.com | C13: guest | D13: hn-esx-prd-6568.roberts-parker.com | E13: WinDesktopLocal | F13: password | G13: 1 | H13: inProcess | L13: 127_641_EXTERNAL-VAULT | M13: Laptops | N13: Laptops_EXTERNAL-VAULT | O13: Credentials for Laptops | P13: EXTERNAL-VAULT | Q13: 34 | R13: 12 | S13: 0 | T13: 0 | U13: 0 | V13: 10 | W13: 28 | X13: 1 | Y13: 18
... A92: Modified | B92: test_01@zw-esx-qa-1517.roberts-parker.com | C92: test_01 | D92: zw-esx-qa-1517.roberts-parker.com | E92: WinDesktopLocal | F92: password | G92: 1 | H92: succeeded | L92: 127_656_EXTERNAL-VAULT | M92: Laptops | N92: Laptops_EXTERNAL-VAULT | O92: Credentials for Laptops | P92: EXTERNAL-VAULT | Q92: 34 | R92: 12 | S92: 0 | T92: 0 | U92: 0 | V92: 10 | W92: 28 | X92: 1 | Y92: 18
A93: Modified | B93: root@al-svr-qa-9369.roberts-parker.com | C93: root | D93: al-svr-qa-9369.roberts-parker.com | E93: WinDesktopLocal | F93: password | G93: 0 | I93: CPM disabled waiting for the end of frozen period | L93: 127_679_EXTERNAL-VAULT | M93: Laptops | N93: Laptops_EXTERNAL-VAULT | O93: Credentials for Laptops | P93: EXTERNAL-VAULT | Q93: 34 | R93: 12 | S93: 0 | T93: 0 | U93: 0 | V93: 10 | W93: 28 | X93: 1 | Y93: 18
A94: Modified | B94: qa@dj-esx-dev-0539.roberts-parker.com | C94: qa | D94: dj-esx-dev-0539.roberts-parker.com | E94: WinDesktopLocal | F94: password | G94: 0 | I94: CPM disabled waiting for the end of frozen period | L94: 127_649_EXTERNAL-VAULT | M94: Laptops | N94: Laptops_EXTERNAL-VAULT | O94: Credentials for Laptops | P94: EXTERNAL-VAULT | Q94: 34 | R94: 12 | S94: 0 | T94: 0 | U94: 0 | V94: 10 | W94: 28 | X94: 1 | Y94: 18
A95: Modified | B95: test_01@ge-svr-dev-1480.roberts-parker.com | C95: test_01 | D95: ge-svr-dev-1480.roberts-parker.com | E95: WinDesktopLocal | F95: password | G95: 0 | I95: CPM disabled waiting for the end of frozen period | L95: 127_685_EXTERNAL-VAULT | M95: Laptops | N95: Laptops_EXTERNAL-VAULT | O95: Credentials for Laptops | P95: EXTERNAL-VAULT | Q95: 34 | R95: 12 | S95: 0 | T95: 0 | U95: 0 | V95: 10 | W95: 28 | X95: 1 | Y95: 18
A96: Modified | B96: super@hn-esx-prd-6568.roberts-parker.com | C96: super | D96: hn-esx-prd-6568.roberts-parker.com | E96: WinDesktopLocal | F96: password | G96: 0 | I96: CPM disabled waiting for the end of frozen period | L96: 127_645_EXTERNAL-VAULT | M96: Laptops | N96: Laptops_EXTERNAL-VAULT | O96: Credentials for Laptops | P96: EXTERNAL-VAULT | Q96: 34 | R96: 12 | S96: 0 | T96: 0 | U96: 0 | V96: 10 | W96: 28 | X96: 1 | Y96: 18
A97: Modified | B97: _batch_@jo-ctx-qa-5577.roberts-parker.com | C97: _batch_ | D97: jo-ctx-qa-5577.roberts-parker.com | E97: WinDesktopLocal | F97: password | G97: 0 | I97: CPM disabled waiting for the end of frozen period | L97: 127_617_EXTERNAL-VAULT | M97: Laptops | N97: Laptops_EXTERNAL-VAULT | O97: Credentials for Laptops | P97: EXTERNAL-VAULT | Q97: 34 | R97: 12 | S97: 0 | T97: 0 | U97: 0 | V97: 10 | W97: 28 | X97: 1 | Y97: 18
A98: Modified | B98: dba@jo-ctx-qa-5577.roberts-parker.com | C98: dba | D98: jo-ctx-qa-5577.roberts-parker.com | E98: WinDesktopLocal | F98: password | G98: 0 | I98: CPM disabled waiting for the end of frozen period | L98: 127_612_EXTERNAL-VAULT | M98: Laptops | N98: Laptops_EXTERNAL-VAULT | O98: Credentials for Laptops | P98: EXTERNAL-VAULT | Q98: 34 | R98: 12 | S98: 0 | T98: 0 | U98: 0 | V98: 10 | W98: 28 | X98: 1 | Y98: 18
A99: Modified | B99: super@jo-ctx-qa-5577.roberts-parker.com | C99: super | D99: jo-ctx-qa-5577.roberts-parker.com | E99: WinDesktopLocal | F99: password | G99: 0 | I99: CPM disabled waiting for the end of frozen period | L99: 127_611_EXTERNAL-VAULT | M99: Laptops | N99: Laptops_EXTERNAL-VAULT | O99: Credentials for Laptops | P99: EXTERNAL-VAULT | Q99: 34 | R99: 12 | S99: 0 | T99: 0 | U99: 0 | V99: 10 | W99: 28 | X99: 1 | Y99: 18
A100: Modified | B100: sa@lt-esx-dev-9197.roberts-parker.com | C100: sa | D100: lt-esx-dev-9197.roberts-parker.com | E100: WinDesktopLocal | F100: password | G100: 0 | I100: CPM disabled waiting for the end of frozen period | L100: 127_632_EXTERNAL-VAULT | M100: Laptops | N100: Laptops_EXTERNAL-VAULT | O100: Credentials for Laptops | P100: EXTERNAL-VAULT | Q100: 34 | R100: 12 | S100: 0 | T100: 0 | U100: 0 | V100: 10 | W100: 28 | X100: 1 | Y100: 18
A101: Modified | B101: operator@pl-des-prd-5826.roberts-parker.com | C101: operator | D101: pl-des-prd-5826.roberts-parker.com | E101: WinDesktopLocal | F101: password | G101: 0 | I101: CPM disabled waiting for the end of frozen period | L101: 127_673_EXTERNAL-VAULT | M101: Laptops | N101: Laptops_EXTERNAL-VAULT | O101: Credentials for Laptops | P101: EXTERNAL-VAULT | Q101: 34 | R101: 12 | S101: 0 | T101: 0 | U101: 0 | V101: 10 | W101: 28 | X101: 1 | Y101: 18
A102: Modified | B102: Administrator@pw-hyp-dev-0754.roberts-parker.com | C102: Administrator | D102: pw-hyp-dev-0754.roberts-parker.com | E102: WinDesktopLocal | F102: password | G102: 0 | I102: CPM disabled waiting for the end of frozen period | L102: 127_603_EXTERNAL-VAULT | M102: Laptops | N102: Laptops_EXTERNAL-VAULT | O102: Credentials for Laptops | P102: EXTERNAL-VAULT | Q102: 34 | R102: 12 | S102: 0 | T102: 0 | U102: 0 | V102: 10 | W102: 28 | X102: 1 | Y102: 18
A103: Modified | B103: super@sr-ctx-prd-5142.roberts-parker.com | C103: super | D103: sr-ctx-prd-5142.roberts-parker.com | E103: WinDesktopLocal | F103: password | G103: 0 | I103: CPM disabled waiting for the end of frozen period | L103: 127_621_EXTERNAL-VAULT | M103: Laptops | N103: Laptops_EXTERNAL-VAULT | O103: Credentials for Laptops | P103: EXTERNAL-VAULT | Q103: 34 | R103: 12 | S103: 0 | T103: 0 | U103: 0 | V103: 10 | W103: 28 | X103: 1 | Y103: 18
A104: Modified | B104: sa@to-des-prd-3745.roberts-parker.com | C104: sa | D104: to-des-prd-3745.roberts-parker.com | E104: WinDesktopLocal | F104: password | G104: 0 | I104: CPM disabled waiting for the end of frozen period | L104: 127_665_EXTERNAL-VAULT | M104: Laptops | N104: Laptops_EXTERNAL-VAULT | O104: Credentials for Laptops | P104: EXTERNAL-VAULT | Q104: 34 | R104: 12 | S104: 0 | T104: 0 | U104: 0 | V104: 10 | W104: 28 | X104: 1 | Y104: 18
A105: Modified | B105: Administrator@ua-des-dev-3219.roberts-parker.com | C105: Administrator | D105: ua-des-dev-3219.roberts-parker.com | E105: WinDesktopLocal | F105: password | G105: 0 | I105: CPM disabled waiting for the end of frozen period | L105: 127_670_EXTERNAL-VAULT | M105: Laptops | N105: Laptops_EXTERNAL-VAULT | O105: Credentials for Laptops | P105: EXTERNAL-VAULT | Q105: 34 | R105: 12 | S105: 0 | T105: 0 | U105: 0 | V105: 10 | W105: 28 | X105: 1 | Y105: 18
A106: credentials

Sheet controldefects
A1: status | B1: controlrisklevel | C1: controldisplayname | D1: EntityType | E1: EntityName | F1: EntityId | G1: EntityDesc | H1: controlnotes | I1: controltagtype | J1: controlriskinfo | K1: controlsuggestedmitigation | L1: safe_displayname | M1: safe_code | N1: vault_displayname | O1: acc_username | P1: repo_displayname | Q1: acc_sid | R1: acc_guid | S1: cred_login | T1: cred_resource | U1: cred_platformid | V1: cred_type | W1: cred_displayname
A2: New | B2: 4 | C2: Remaining Active Users | D2: User Account | E2: AGARDNER14 | F2: CN=Alexis GARDNER,OU=Users,OU=ACME,DC=acme,DC=corp | H2: Active user accounts belonging to an identity who has left the company and that has access to a CyberArk Safe. | I2: risk | J2: User accounts must be terminated upon their owner's departure or risk being used by a third party (insider, hacker) to compromise the data or steal information. | K2: Verify that the owner has left the company and immediately disable the account. | L2: Laptops | M2: Laptops_EXTERNAL-VAULT | N2: EXTERNAL-VAULT | O2: Alexis GARDNER | P2: ACME | Q2: S-1-5-21-2198405017-3190945858-2291852294-1252 | R2: 40305f5a-3202-4c03-a399-e8fdf9472d80
A3: New | B3: 4 | C3: Remaining Active Users | D3: User Account | E3: KMCDANIE16 | F3: CN=Katie MCDANIEL,OU=Users,OU=ACME,DC=acme,DC=corp | H3: Active user accounts belonging to an identity who has left the company and that has access to a CyberArk Safe. | I3: risk | J3: User accounts must be terminated upon their owner's departure or risk being used by a third party (insider, hacker) to compromise the data or steal information. | K3: Verify that the owner has left the company and immediately disable the account. | L3: Laptops | M3: Laptops_EXTERNAL-VAULT | N3: EXTERNAL-VAULT | O3: Katie MCDANIEL | P3: ACME | Q3: S-1-5-21-2198405017-3190945858-2291852294-1217 | R3: 831d0801-f828-4de0-9968-8ddac9d05f73
A4: New | B4: 4 | C4: Remaining Active Users | D4: User Account | E4: NREED10 | F4: CN=Neil REED,OU=Users,OU=ACME,DC=acme,DC=corp | H4: Active user accounts belonging to an identity who has left the company and that has access to a CyberArk Safe. | I4: risk | J4: User accounts must be terminated upon their owner's departure or risk being used by a third party (insider, hacker) to compromise the data or steal information. | K4: Verify that the owner has left the company and immediately disable the account. | L4: Laptops | M4: Laptops_EXTERNAL-VAULT | N4: EXTERNAL-VAULT | O4: Neil REED | P4: ACME | Q4: S-1-5-21-2198405017-3190945858-2291852294-1318 | R4: 66b1e624-9c7a-49f5-930a-52d6faa9e65b
A5: New | B5: 4 | C5: Remaining Active Users | D5: User Account | E5: SMURPHY16 | F5: CN=Steven MURPHY,OU=Users,OU=ACME,DC=acme,DC=corp | H5: Active user accounts belonging to an identity who has left the company and that has access to a CyberArk Safe. | I5: risk | J5: User accounts must be terminated upon their owner's departure or risk being used by a third party (insider, hacker) to compromise the data or steal information. | K5: Verify that the owner has left the company and immediately disable the account. | L5: Laptops | M5: Laptops_EXTERNAL-VAULT | N5: EXTERNAL-VAULT | O5: Steven MURPHY | P5: ACME | Q5: S-1-5-21-2198405017-3190945858-2291852294-1113 | R5: 97387029-8747-4316-8b95-d10aae8bcfa7
A6: New | B6: 4 | C6: Remaining Active Users | D6: User Account | E6: THENDERS13 | F6: CN=Tonya HENDERSON,OU=Users,OU=ACME,DC=acme,DC=corp | H6: Active user accounts belonging to an identity who has left the company and that has access to a CyberArk Safe. | I6: risk | J6: User accounts must be terminated upon their owner's departure or risk being used by a third party (insider, hacker) to compromise the data or steal information. | K6: Verify that the owner has left the company and immediately disable the account. | L6: Laptops | M6: Laptops_EXTERNAL-VAULT | N6: EXTERNAL-VAULT | O6: Tonya HENDERSON | P6: ACME | Q6: S-1-5-21-2198405017-3190945858-2291852294-1319 | R6: ccec6db2-9b8c-492b-a891-b9431970195d
A7: New | B7: 4 | C7: Contractors who Can Manage my Safes without Expiration | D7: User Account | E7: MCANNON18 | F7: CN=Meghan CANNON,OU=Users,OU=ACME,DC=acme,DC=corp | H7: Active identity who is a contractor and has a user account without an expiration date that can administer a CyberArk safe. | I7: risk | J7: Contractor user accounts should have an expiration date to facilitate account revocation. | K7: Add an expiration date to the contractor user account. | L7: Laptops | M7: Laptops_EXTERNAL-VAULT | N7: EXTERNAL-VAULT | O7: Meghan CANNON | P7: ACME | Q7: S-1-5-21-2198405017-3190945858-2291852294-1256 | R7: 31bbcb7e-3ebb-4b6f-9fcc-b6cec7cf4813
A8: New | B8: 4 | C8: Contractors who Can Use my Credentials without Expiration | D8: User Account | E8: MCANNON18 | F8: CN=Meghan CANNON,OU=Users,OU=ACME,DC=acme,DC=corp | H8: User accounts without an expiration date belonging to active identities who are contractors and who can access a CyberArk safe. | I8: risk | J8: Contractor user accounts should have an expiration date to faciliate account revocation. | K8: Add an expiration date to the contractor user account. | L8: Laptops | M8: Laptops_EXTERNAL-VAULT | N8: EXTERNAL-VAULT | O8: Meghan CANNON | P8: ACME | Q8: S-1-5-21-2198405017-3190945858-2291852294-1256 | R8: 31bbcb7e-3ebb-4b6f-9fcc-b6cec7cf4813
A9: Identical | B9: 3 | C9: New Credentials without CPM | D9: Credential | E9: Administrator@pw-hyp-dev-0754.roberts-parker.com | F9: 127_603_EXTERNAL-VAULT | G9: PlatformID: WinDesktopLocal Secret Type: password | H9: Once privileged accounts are onboarded in CyberArk, their usage is not completely secure until the CPM is activated. | I9: risk | J9: End users can still bypass CyberArk to use these privileged accounts because the password is not automatically changed by the CyberArk CPM. | K9: Contact the resource owner and the CyberArk team about activating CPM on these privileged accounts. | L9: Laptops | M9: Laptops_EXTERNAL-VAULT | N9: EXTERNAL-VAULT | S9: Administrator | T9: pw-hyp-dev-0754.roberts-parker.com | U9: WinDesktopLocal | V9: password | W9: pw-hyp-dev-0754.roberts-parker.com-Administrator-251d8b60-e34a-4371-8caf-0e378ff850f69
A10: Identical | B10: 3 | C10: New Credentials without CPM | D10: Credential | E10: super@jo-ctx-qa-5577.roberts-parker.com | F10: 127_611_EXTERNAL-VAULT | G10: PlatformID: WinDesktopLocal Secret Type: password | H10: Once privileged accounts are onboarded in CyberArk, their usage is not completely secure until the CPM is activated. | I10: risk | J10: End users can still bypass CyberArk to use these privileged accounts because the password is not automatically changed by the CyberArk CPM. | K10: Contact the resource owner and the CyberArk team about activating CPM on these privileged accounts. | L10: Laptops | M10: Laptops_EXTERNAL-VAULT | N10: EXTERNAL-VAULT | S10: super | T10: jo-ctx-qa-5577.roberts-parker.com | U10: WinDesktopLocal | V10: password | W10: jo-ctx-qa-5577.roberts-parker.com-super-251d8b60-e34a-4371-8caf-0e378ff850f71
